I'm sorry, but an uncaught exception occurred.

While running game code:
  File "game/script.rpy", line 36, in script call
    call phone_jlo
  File "game/phone/definitions/01definitions.rpy", line 127, in script
    phone discussion "mc_sayo_gc_j": # using the gc's key
  File "game/01statements.rpy", line 32, in execute
    rv.execute()
  File "game/01statements.rpy", line 408, in execute
    if gc is not None: gc = group_chat.group_chat(eval(gc, store.__dict__))
  File "game/phone/apps/discussion/group_chats.rpy", line 142, in group_chat
    raise KeyError("no group chat with the key %r exists (check your definitions)" % x)
KeyError: "no group chat with the key 'mc_sayo_gc_j' exists (check your definitions)"

-- Full Traceback ------------------------------------------------------------

Full traceback:
  File "game/script.rpy", line 36, in script call
    call phone_jlo
  File "game/phone/definitions/01definitions.rpy", line 127, in script
    phone discussion "mc_sayo_gc_j": # using the gc's key
  File "D:\Projekte\Nov\renpy-8.1.3-sdk\renpy\ast.py", line 2259, in execute
    self.call("execute")
  File "D:\Projekte\Nov\renpy-8.1.3-sdk\renpy\ast.py", line 2241, in call
    return renpy.statements.call(method, parsed, *args, **kwargs)
  File "D:\Projekte\Nov\renpy-8.1.3-sdk\renpy\statements.py", line 342, in call
    return method(parsed, *args, **kwargs)
  File "game/01statements.rpy", line 32, in execute
    rv.execute()
  File "game/01statements.rpy", line 408, in execute
    if gc is not None: gc = group_chat.group_chat(eval(gc, store.__dict__))
  File "game/phone/apps/discussion/group_chats.rpy", line 142, in group_chat
    raise KeyError("no group chat with the key %r exists (check your definitions)" % x)
KeyError: "no group chat with the key 'mc_sayo_gc_j' exists (check your definitions)"

Windows-10-10.0.19045 AMD64
Ren'Py 8.1.3.23091805
Handytest 1.0
Thu Feb  8 13:44:29 2024
